use anyhow::{bail, Result};

use crate::{
    iterators::{merge_iterator::MergeIterator, StorageIterator},
    mem_table::MemTableIterator,
};

/// Represents the internal type for an LSM iterator. This type will be changed across the tutorial for multiple times.
type LsmIteratorInner = MergeIterator<MemTableIterator>;

pub struct LsmIterator {
    inner: LsmIteratorInner,
}

fn skip_deleted_keys_values(iter: &mut LsmIteratorInner) -> Result<()> {
    // Skip deleted keys values
    while iter.is_valid() && iter.value().is_empty() {
        iter.next()?;
    }
    Ok(())
}

impl LsmIterator {
    pub(crate) fn new(mut iter: LsmIteratorInner) -> Result<Self> {
        skip_deleted_keys_values(&mut iter)?;
        Ok(Self { inner: iter })
    }
}

impl StorageIterator for LsmIterator {
    type KeyType<'a> = &'a [u8];

    fn is_valid(&self) -> bool {
        self.inner.is_valid()
    }

    fn key(&self) -> &[u8] {
        self.inner.key().raw_ref()
    }

    fn value(&self) -> &[u8] {
        self.inner.value()
    }

    fn next(&mut self) -> Result<()> {
        self.inner.next()?;
        skip_deleted_keys_values(&mut self.inner)?;
        Ok(())
    }
}

/// A wrapper around existing iterator, will prevent users from calling `next` when the iterator is
/// invalid. If an iterator is already invalid, `next` does not do anything. If `next` returns an error,
/// `is_valid` should return false, and `next` should always return an error.
pub struct FusedIterator<I: StorageIterator> {
    iter: I,
    has_errored: bool,
}

impl<I: StorageIterator> FusedIterator<I> {
    pub fn new(iter: I) -> Self {
        Self {
            iter,
            has_errored: false,
        }
    }
}

impl<I: StorageIterator> StorageIterator for FusedIterator<I> {
    type KeyType<'a>
        = I::KeyType<'a>
    where
        Self: 'a;

    fn is_valid(&self) -> bool {
        !self.has_errored && self.iter.is_valid()
    }

    fn key(&self) -> Self::KeyType<'_> {
        self.iter.key()
    }

    fn value(&self) -> &[u8] {
        self.iter.value()
    }

    fn next(&mut self) -> Result<()> {
        if self.has_errored {
            bail!("calling `next()` on an errored iterator.")
        }

        if let Err(e) = self.iter.next() {
            self.has_errored = true;
            return Err(e);
        }

        Ok(())
    }
}
